Traceback (most recent call last):
  File "/Users/saskiad/opt/anaconda3/lib/python3.9/site-packages/jupyter_cache/executors/utils.py", line 51, in single_nb_execution
    executenb(
  File "/Users/saskiad/opt/anaconda3/lib/python3.9/site-packages/nbclient/client.py", line 1204, in execute
    return NotebookClient(nb=nb, resources=resources, km=km, **kwargs).execute()
  File "/Users/saskiad/opt/anaconda3/lib/python3.9/site-packages/nbclient/util.py", line 84, in wrapped
    return just_run(coro(*args, **kwargs))
  File "/Users/saskiad/opt/anaconda3/lib/python3.9/site-packages/nbclient/util.py", line 62, in just_run
    return loop.run_until_complete(coro)
  File "/Users/saskiad/opt/anaconda3/lib/python3.9/asyncio/base_events.py", line 647, in run_until_complete
    return future.result()
  File "/Users/saskiad/opt/anaconda3/lib/python3.9/site-packages/nbclient/client.py", line 663, in async_execute
    await self.async_execute_cell(
  File "/Users/saskiad/opt/anaconda3/lib/python3.9/site-packages/nbclient/client.py", line 965, in async_execute_cell
    await self._check_raise_for_error(cell, cell_index, exec_reply)
  File "/Users/saskiad/opt/anaconda3/lib/python3.9/site-packages/nbclient/client.py", line 862, in _check_raise_for_error
    raise CellExecutionError.from_cell_and_msg(cell, exec_reply_content)
nbclient.exceptions.CellExecutionError: An error occurred while executing the following cell:
------------------
import scipy.stats as st
r,p = st.pearsonr(nm_a, nm_b)
print("AB Correlation = ", str(r))

r,p = st.pearsonr(nm_a, nm_c)
print("AC Correlation = ", str(r))

r,p = st.pearsonr(nm_b, nm_c)
print("BC Correlation = ", str(r))
------------------

[0;31m---------------------------------------------------------------------------[0m
[0;31mValueError[0m                                Traceback (most recent call last)
[0;32m/var/folders/qh/5lyvn7d93mzft9kchq7xsqkw0000gp/T/ipykernel_99774/1618745026.py[0m in [0;36m<module>[0;34m[0m
[1;32m      1[0m [0;32mimport[0m [0mscipy[0m[0;34m.[0m[0mstats[0m [0;32mas[0m [0mst[0m[0;34m[0m[0;34m[0m[0m
[0;32m----> 2[0;31m [0mr[0m[0;34m,[0m[0mp[0m [0;34m=[0m [0mst[0m[0;34m.[0m[0mpearsonr[0m[0;34m([0m[0mnm_a[0m[0;34m,[0m [0mnm_b[0m[0;34m)[0m[0;34m[0m[0;34m[0m[0m
[0m[1;32m      3[0m [0mprint[0m[0;34m([0m[0;34m"AB Correlation = "[0m[0;34m,[0m [0mstr[0m[0;34m([0m[0mr[0m[0;34m)[0m[0;34m)[0m[0;34m[0m[0;34m[0m[0m
[1;32m      4[0m [0;34m[0m[0m
[1;32m      5[0m [0mr[0m[0;34m,[0m[0mp[0m [0;34m=[0m [0mst[0m[0;34m.[0m[0mpearsonr[0m[0;34m([0m[0mnm_a[0m[0;34m,[0m [0mnm_c[0m[0;34m)[0m[0;34m[0m[0;34m[0m[0m

[0;32m~/opt/anaconda3/lib/python3.9/site-packages/scipy/stats/_stats_py.py[0m in [0;36mpearsonr[0;34m(x, y, alternative)[0m
[1;32m   4461[0m         [0mwarnings[0m[0;34m.[0m[0mwarn[0m[0;34m([0m[0mstats[0m[0;34m.[0m[0mNearConstantInputWarning[0m[0;34m([0m[0mmsg[0m[0;34m)[0m[0;34m)[0m[0;34m[0m[0;34m[0m[0m
[1;32m   4462[0m [0;34m[0m[0m
[0;32m-> 4463[0;31m     [0mr[0m [0;34m=[0m [0mnp[0m[0;34m.[0m[0mdot[0m[0;34m([0m[0mxm[0m[0;34m/[0m[0mnormxm[0m[0;34m,[0m [0mym[0m[0;34m/[0m[0mnormym[0m[0;34m)[0m[0;34m[0m[0;34m[0m[0m
[0m[1;32m   4464[0m [0;34m[0m[0m
[1;32m   4465[0m     [0;31m# Presumably, if abs(r) > 1, then it is only some small artifact of[0m[0;34m[0m[0;34m[0m[0m

[0;32m~/opt/anaconda3/lib/python3.9/site-packages/numpy/core/overrides.py[0m in [0;36mdot[0;34m(*args, **kwargs)[0m

[0;31mValueError[0m: shapes (900,10) and (900,10) not aligned: 10 (dim 1) != 900 (dim 0)
ValueError: shapes (900,10) and (900,10) not aligned: 10 (dim 1) != 900 (dim 0)

