Traceback (most recent call last):
  File "/Users/saskiad/opt/anaconda3/lib/python3.9/site-packages/jupyter_cache/executors/utils.py", line 51, in single_nb_execution
    executenb(
  File "/Users/saskiad/opt/anaconda3/lib/python3.9/site-packages/nbclient/client.py", line 1204, in execute
    return NotebookClient(nb=nb, resources=resources, km=km, **kwargs).execute()
  File "/Users/saskiad/opt/anaconda3/lib/python3.9/site-packages/nbclient/util.py", line 84, in wrapped
    return just_run(coro(*args, **kwargs))
  File "/Users/saskiad/opt/anaconda3/lib/python3.9/site-packages/nbclient/util.py", line 62, in just_run
    return loop.run_until_complete(coro)
  File "/Users/saskiad/opt/anaconda3/lib/python3.9/asyncio/base_events.py", line 647, in run_until_complete
    return future.result()
  File "/Users/saskiad/opt/anaconda3/lib/python3.9/site-packages/nbclient/client.py", line 663, in async_execute
    await self.async_execute_cell(
  File "/Users/saskiad/opt/anaconda3/lib/python3.9/site-packages/nbclient/client.py", line 965, in async_execute_cell
    await self._check_raise_for_error(cell, cell_index, exec_reply)
  File "/Users/saskiad/opt/anaconda3/lib/python3.9/site-packages/nbclient/client.py", line 862, in _check_raise_for_error
    raise CellExecutionError.from_cell_and_msg(cell, exec_reply_content)
nbclient.exceptions.CellExecutionError: An error occurred while executing the following cell:
------------------
running_trials = stim_table[(stim_table.frame==preferred_image)&(df.speed>2)].index.values
stationary_trials = stim_table[(stim_table.frame==preferred_image)&(df.speed<2)].index.values

for trial in stationary_trials:
    plt.plot(dff[cell_index, stim_table.start.loc[trial]-30:stim_table.end.loc[trial]+30], color='blue')
for trial in running_trials:
    plt.plot(dff[cell_index, stim_table.start.loc[trial]-30:stim_table.end.loc[trial]+30], color='red')
plt.axvpan(xmin=30, xmax=37, color='gray', alpha=0.1)
------------------

[0;31m---------------------------------------------------------------------------[0m
[0;31mAttributeError[0m                            Traceback (most recent call last)
[0;32m/var/folders/qh/5lyvn7d93mzft9kchq7xsqkw0000gp/T/ipykernel_4503/2386959523.py[0m in [0;36m<module>[0;34m[0m
[1;32m      6[0m [0;32mfor[0m [0mtrial[0m [0;32min[0m [0mrunning_trials[0m[0;34m:[0m[0;34m[0m[0;34m[0m[0m
[1;32m      7[0m     [0mplt[0m[0;34m.[0m[0mplot[0m[0;34m([0m[0mdff[0m[0;34m[[0m[0mcell_index[0m[0;34m,[0m [0mstim_table[0m[0;34m.[0m[0mstart[0m[0;34m.[0m[0mloc[0m[0;34m[[0m[0mtrial[0m[0;34m][0m[0;34m-[0m[0;36m30[0m[0;34m:[0m[0mstim_table[0m[0;34m.[0m[0mend[0m[0;34m.[0m[0mloc[0m[0;34m[[0m[0mtrial[0m[0;34m][0m[0;34m+[0m[0;36m30[0m[0;34m][0m[0;34m,[0m [0mcolor[0m[0;34m=[0m[0;34m'red'[0m[0;34m)[0m[0;34m[0m[0;34m[0m[0m
[0;32m----> 8[0;31m [0mplt[0m[0;34m.[0m[0maxvpan[0m[0;34m([0m[0mxmin[0m[0;34m=[0m[0;36m30[0m[0;34m,[0m [0mxmax[0m[0;34m=[0m[0;36m37[0m[0;34m,[0m [0mcolor[0m[0;34m=[0m[0;34m'gray'[0m[0;34m,[0m [0malpha[0m[0;34m=[0m[0;36m0.1[0m[0;34m)[0m[0;34m[0m[0;34m[0m[0m
[0m
[0;31mAttributeError[0m: module 'matplotlib.pyplot' has no attribute 'axvpan'
AttributeError: module 'matplotlib.pyplot' has no attribute 'axvpan'

